---
title: "Post 918847"
---
<p><i><a href="https://github.com/MSDN-WhiteKnight/ruso-archive/">RuSO Archive</a></i></p>
<h1>Post 918847</h1>
<h2>Answer 918847</h2>
<p><a href="https://ru.stackoverflow.com/a/918847/">Source</a> - by <a href="https://ru.stackoverflow.com/users/240512/msdn-whiteknight">MSDN.WhiteKnight</a></p>
<blockquote>
<p>У меня вот так работает</p>

<p>C#:</p>

<pre><code>using System;
using System.Collections.Generic;
using System.Runtime.InteropServices;
using System.Text;

namespace AxTest
{
    [ProgId("AxTest.Class1")]
    [ClassInterface(ClassInterfaceType.AutoDual)]
    [Guid("177E405F-0C29-4FB1-B55A-D5324EDE1E97")]
    [ComVisible(true)]
    public class Class1 
    {
        public string Test(string x)
        {
            throw new Exception("Something bad happened!");
        }        

    }
}
</code></pre>

<p>JS:</p>

<pre><code>&lt;html&gt;
   &lt;head&gt;
          &lt;title&gt;ActiveX test&lt;/title&gt;
   &lt;/head&gt;
   &lt;body&gt;
        &lt;script type="text/jscript"&gt;

            try {

                var customObject = new ActiveXObject("AxTest.Class1");
                var res = customObject.Test("Foo");
                alert(res);

            } catch (ex) {

                alert("Exception: " + ex.message);

            }


        &lt;/script&gt;
   &lt;/body&gt;
&lt;/html&gt;
</code></pre>

<p>Судя по сообщению, у вас исключение завернуто в TargetInvocationException. Чтобы получить нормальное сообщение об ошибке, вам надо его перехватывать и пробрасывать как свое исключение. Потому что в JS не достать InnerException.</p>

</blockquote>
<hr/>
<p><i>Content is retrieved from StackExchange API. </i></p>
<p><i>Auto-generated by ruso-archive tools. </i></p>
