---
title: "Перехват исключения при делении на 0"
se.owner.user_id: 255680
se.owner.display_name: "Александр"
se.owner.link: "https://ru.stackoverflow.com/users/255680/%d0%90%d0%bb%d0%b5%d0%ba%d1%81%d0%b0%d0%bd%d0%b4%d1%80"
se.link: "https://ru.stackoverflow.com/questions/842745/%d0%9f%d0%b5%d1%80%d0%b5%d1%85%d0%b2%d0%b0%d1%82-%d0%b8%d1%81%d0%ba%d0%bb%d1%8e%d1%87%d0%b5%d0%bd%d0%b8%d1%8f-%d0%bf%d1%80%d0%b8-%d0%b4%d0%b5%d0%bb%d0%b5%d0%bd%d0%b8%d0%b8-%d0%bd%d0%b0-0"
se.question_id: 842745
se.post_type: question
se.score: 2
---
<p>Пытаюсь отловить исключение через catch/try: </p>

<pre><code>void TestCall()
{
    int b=0;
    try
    {

        int a = 1/b;        
    }
    catch(...)
    {
        test(1);
    }
}
</code></pre>

<p>Выражение <code>int a = 1/b;</code> заведомо вызывает исключение деления на 0 и я хоч его поймать в блоке catch. Но Visual C++ упорно вызывает ошибку на нем и на catch не перекидывает. В чем секрет?</p>
