{"tags":["c++"],"owner":{"reputation":715,"user_id":255680,"user_type":"registered","accept_rate":75,"profile_image":"https://lh3.googleusercontent.com/-XdUIqdMkCWA/AAAAAAAAAAI/AAAAAAAAAAA/4252rscbv5M/photo.jpg?sz=128","display_name":"Александр","link":"https://ru.stackoverflow.com/users/255680/%d0%90%d0%bb%d0%b5%d0%ba%d1%81%d0%b0%d0%bd%d0%b4%d1%80"},"is_answered":true,"view_count":149,"accepted_answer_id":842747,"answer_count":2,"score":2,"last_activity_date":1529551840,"creation_date":1529143534,"last_edit_date":1529144088,"question_id":842745,"link":"https://ru.stackoverflow.com/questions/842745/%d0%9f%d0%b5%d1%80%d0%b5%d1%85%d0%b2%d0%b0%d1%82-%d0%b8%d1%81%d0%ba%d0%bb%d1%8e%d1%87%d0%b5%d0%bd%d0%b8%d1%8f-%d0%bf%d1%80%d0%b8-%d0%b4%d0%b5%d0%bb%d0%b5%d0%bd%d0%b8%d0%b8-%d0%bd%d0%b0-0","title":"Перехват исключения при делении на 0","body":"<p>Пытаюсь отловить исключение через catch/try: </p>\n\n<pre><code>void TestCall()\n{\n    int b=0;\n    try\n    {\n\n        int a = 1/b;        \n    }\n    catch(...)\n    {\n        test(1);\n    }\n}\n</code></pre>\n\n<p>Выражение <code>int a = 1/b;</code> заведомо вызывает исключение деления на 0 и я хоч его поймать в блоке catch. Но Visual C++ упорно вызывает ошибку на нем и на catch не перекидывает. В чем секрет?</p>\n"}