---
title: "Ошибка скомпилированной с помощью Nuitka программы на Python"
se.owner.user_id: 406594
se.owner.display_name: "Helg1980"
se.owner.link: "https://ru.meta.stackoverflow.com/users/406594/helg1980"
se.link: "https://ru.meta.stackoverflow.com/questions/10851/%d0%9e%d1%88%d0%b8%d0%b1%d0%ba%d0%b0-%d1%81%d0%ba%d0%be%d0%bc%d0%bf%d0%b8%d0%bb%d0%b8%d1%80%d0%be%d0%b2%d0%b0%d0%bd%d0%bd%d0%be%d0%b9-%d1%81-%d0%bf%d0%be%d0%bc%d0%be%d1%89%d1%8c%d1%8e-nuitka-%d0%bf%d1%80%d0%be%d0%b3%d1%80%d0%b0%d0%bc%d0%bc%d1%8b-%d0%bd%d0%b0-python"
se.question_id: 10851
se.post_type: question
---
<p>У меня возникла проблема скомпилированной с помощью Nuitka программы на Python 3.8
<a href="https://github.com/CineEncoder/cine-encoder/tree/master/cine_encoder" rel="nofollow noreferrer">https://github.com/CineEncoder/cine-encoder/tree/master/cine_encoder</a> с использованием PyQt5 и QProcess (с которым, как мне кажется, и связана проблема),
скомпилированная программа аварийно закрывается, вот вывод консоли:</p>
<pre><code>[helg@Houston ~]$ /run/media/helg/GOODRAM-SDB/MakePackage/BIN/Linux/cine-encoder-2.4_other_linux_x86_64/App/CineEncoder.run 
Fontconfig warning: &quot;/etc/fonts/conf.avail/05-reset-dirs-sample.conf&quot;, line 6: unknown element &quot;reset-dirs&quot;
qt.qpa.xcb: QXcbConnection: XCB error: 3 (BadWindow), sequence: 684, resource id: 14689761, major code: 40 (TranslateCoords), minor code: 0
Traceback (most recent call last):
  File &quot;/run/media/helg/GOODRAM-SDB/MakePackage/BIN/Linux/cine-encoder-2.4_other_linux_x86_64/App/main.py&quot;, line 1104, in progress_1
TypeError: 'compiled_method' object is not connected
Aborted (core dumped)
[helg@Houston ~]$ 
</code></pre>
<p>Как мне кажется, ошибка соответствует этим строкам кода Python (в файле main.py):</p>
<pre><code>...
1135   if (percent &gt;= 50) and (calling_pr_1 is True):
1136        self.procedure_1.finished.disconnect(self.error)
1137        self.procedure_1.finished.connect(self.add_metadata)
1138        calling_pr_1 = False
...
</code></pre>
<p>При том, что при запуске оригинальной версии программы через Python 3.8, никаких ошибок нет.</p>
<p>Для компиляции я использовал команду:</p>
<pre><code>python -m nuitka --standalone --plugin-enable=qt-plugins main.py
</code></pre>
<p>Вот ссылка к скомпилированной программе: <a href="https://github.com/CineEncoder/cine-encoder/releases/download/2.4/cine-encoder-2.4_other_linux_x86_64.zip" rel="nofollow noreferrer">https://github.com/CineEncoder/cine-encoder/releases/download/2.4/cine-encoder-2.4_other_linux_x86_64.zip</a></p>
<p>Версии приложений:</p>
<pre><code>[helg@Houston ~]$   python -m nuitka --version
0.6.8
Python: 3.8.5 (default, Sep  5 2020, 10:50:12) 
Executable: /usr/bin/python
OS: Linux
Arch: x86_64
</code></pre>
